Watching for file changes with StatReloader
Performing system checks...

System check identified no issues (0 silenced).
Exception in thread django-main-thread:
Traceback (most recent call last):
  File "C:\Users\MIDI-PC\AppData\Local\Programs\Python\Python313\Lib\threading.py", line 1041, in _bootstrap_inner
    self.run()
    ~~~~~~~~^^
  File "C:\Users\MIDI-PC\AppData\Local\Programs\Python\Python313\Lib\threading.py", line 992, in run
    self._target(*self._args, **self._kwargs)
    ~~~~~~~~~~~~^^^^^^^^^^^^^^^^^^^^^^^^^^^^^
  File "C:\Users\MIDI-PC\Desktop\backend\250729_final project\venv\Lib\site-packages\django\utils\autoreload.py", line 64, in wrapper
    fn(*args, **kwargs)
    ~~^^^^^^^^^^^^^^^^^
  File "C:\Users\MIDI-PC\Desktop\backend\250729_final project\venv\Lib\site-packages\django\core\management\commands\runserver.py", line 137, in inner_run
    self.check_migrations()
    ~~~~~~~~~~~~~~~~~~~~~^^
  File "C:\Users\MIDI-PC\Desktop\backend\250729_final project\venv\Lib\site-packages\django\core\management\base.py", line 587, in check_migrations
    executor = MigrationExecutor(connections[DEFAULT_DB_ALIAS])
  File "C:\Users\MIDI-PC\Desktop\backend\250729_final project\venv\Lib\site-packages\django\db\migrations\executor.py", line 18, in __init__
    self.loader = MigrationLoader(self.connection)
                  ~~~~~~~~~~~~~~~^^^^^^^^^^^^^^^^^
  File "C:\Users\MIDI-PC\Desktop\backend\250729_final project\venv\Lib\site-packages\django\db\migrations\loader.py", line 58, in __init__
    self.build_graph()
    ~~~~~~~~~~~~~~~~^^
  File "C:\Users\MIDI-PC\Desktop\backend\250729_final project\venv\Lib\site-packages\django\db\migrations\loader.py", line 235, in build_graph
    self.applied_migrations = recorder.applied_migrations()
                              ~~~~~~~~~~~~~~~~~~~~~~~~~~~^^
  File "C:\Users\MIDI-PC\Desktop\backend\250729_final project\venv\Lib\site-packages\django\db\migrations\recorder.py", line 89, in applied_migrations
    if self.has_table():
       ~~~~~~~~~~~~~~^^
  File "C:\Users\MIDI-PC\Desktop\backend\250729_final project\venv\Lib\site-packages\django\db\migrations\recorder.py", line 63, in has_table
    with self.connection.cursor() as cursor:
         ~~~~~~~~~~~~~~~~~~~~~~^^
  File "C:\Users\MIDI-PC\Desktop\backend\250729_final project\venv\Lib\site-packages\django\utils\asyncio.py", line 26, in inner
    return func(*args, **kwargs)
  File "C:\Users\MIDI-PC\Desktop\backend\250729_final project\venv\Lib\site-packages\django\db\backends\base\base.py", line 320, in cursor
    return self._cursor()
           ~~~~~~~~~~~~^^
  File "C:\Users\MIDI-PC\Desktop\backend\250729_final project\venv\Lib\site-packages\django\db\backends\base\base.py", line 296, in _cursor
    self.ensure_connection()
    ~~~~~~~~~~~~~~~~~~~~~~^^
  File "C:\Users\MIDI-PC\Desktop\backend\250729_final project\venv\Lib\site-packages\django\utils\asyncio.py", line 26, in inner
    return func(*args, **kwargs)
  File "C:\Users\MIDI-PC\Desktop\backend\250729_final project\venv\Lib\site-packages\django\db\backends\base\base.py", line 279, in ensure_connection
    self.connect()
    ~~~~~~~~~~~~^^
  File "C:\Users\MIDI-PC\Desktop\backend\250729_final project\venv\Lib\site-packages\django\utils\asyncio.py", line 26, in inner
    return func(*args, **kwargs)
  File "C:\Users\MIDI-PC\Desktop\backend\250729_final project\venv\Lib\site-packages\django\db\backends\base\base.py", line 256, in connect
    self.connection = self.get_new_connection(conn_params)
                      ~~~~~~~~~~~~~~~~~~~~~~~^^^^^^^^^^^^^
  File "C:\Users\MIDI-PC\Desktop\backend\250729_final project\venv\Lib\site-packages\django\utils\asyncio.py", line 26, in inner
    return func(*args, **kwargs)
  File "C:\Users\MIDI-PC\Desktop\backend\250729_final project\venv\Lib\site-packages\django\db\backends\postgresql\base.py", line 332, in get_new_connection
    connection = self.Database.connect(**conn_params)
  File "C:\Users\MIDI-PC\Desktop\backend\250729_final project\venv\Lib\site-packages\psycopg2\__init__.py", line 135, in connect
    conn = _connect(dsn, connection_factory=connection_factory, **kwasync)
UnicodeDecodeError: 'utf-8' codec can't decode byte 0xb8 in position 63: invalid start byte