(venv) PS C:\Users\MIDI-PC\Desktop\backend\250729_final project> python manage.py load_dummy_data --clear 
Clearing all existing data...
Deleting all Report objects...
Deleting all Follow objects...
Deleting all Comment objects...
Deleting all Like objects...
Deleting all Message objects...
Deleting all ChatRoom objects...
Deleting all Product objects...
Deleting all Post objects...
Deleting all UserProfile objects...
Deleting all Category objects...
Deleting all User objects...
All existing data cleared.
Parsing dummy data from er2.txt...
Dummy data parsed successfully.
Loading data into database...
Creating User instances...
Creating Category instances...
Creating UserProfile instances...
Error creating UserProfile 1: Cannot assign "'User 1'": "UserProfile.user" must be a "User" instance.
Traceback (most recent call last):
  File "C:\Users\MIDI-PC\Desktop\backend\250729_final project\manage.py", line 22, in <module>
    main()
    ~~~~^^
  File "C:\Users\MIDI-PC\Desktop\backend\250729_final project\manage.py", line 18, in main
    execute_from_command_line(sys.argv)
    ~~~~~~~~~~~~~~~~~~~~~~~~~^^^^^^^^^^
  File "C:\Users\MIDI-PC\Desktop\backend\250729_final project\venv\Lib\site-packages\django\core\management\__init__.py", line 442, in execute_from_command_line
    utility.execute()
    ~~~~~~~~~~~~~~~^^
  File "C:\Users\MIDI-PC\Desktop\backend\250729_final project\venv\Lib\site-packages\django\core\management\__init__.py", line 436, in execute    
    self.fetch_command(subcommand).run_from_argv(self.argv)
    ~~~~~~~~~~~~~~~~~~~~~~~~~~~~~~~~~~~~~~~~~~~~^^^^^^^^^^^
  File "C:\Users\MIDI-PC\Desktop\backend\250729_final project\venv\Lib\site-packages\django\core\management\base.py", line 416, in run_from_argv  
    self.execute(*args, **cmd_options)
    ~~~~~~~~~~~~^^^^^^^^^^^^^^^^^^^^^^
  File "C:\Users\MIDI-PC\Desktop\backend\250729_final project\venv\Lib\site-packages\django\core\management\base.py", line 460, in execute        
    output = self.handle(*args, **options)
  File "C:\Users\MIDI-PC\Desktop\backend\250729_final project\users\management\commands\load_dummy_data.py", line 33, in handle
    self._load_data(parsed_data)
    ~~~~~~~~~~~~~~~^^^^^^^^^^^^^
  File "C:\Users\MIDI-PC\Desktop\backend\250729_final project\users\management\commands\load_dummy_data.py", line 173, in _load_data
    instance = Model.objects.create(**data_for_creation)
  File "C:\Users\MIDI-PC\Desktop\backend\250729_final project\venv\Lib\site-packages\django\db\models\manager.py", line 87, in manager_method     
    return getattr(self.get_queryset(), name)(*args, **kwargs)
           ~~~~~~~~~~~~~~~~~~~~~~~~~~~~~~~~~~^^^^^^^^^^^^^^^^^
  File "C:\Users\MIDI-PC\Desktop\backend\250729_final project\venv\Lib\site-packages\django\db\models\query.py", line 661, in create
    obj = self.model(**kwargs)
  File "C:\Users\MIDI-PC\Desktop\backend\250729_final project\venv\Lib\site-packages\django\db\models\base.py", line 545, in __init__
    _setattr(self, field.name, rel_obj)
    ~~~~~~~~^^^^^^^^^^^^^^^^^^^^^^^^^^^
  File "C:\Users\MIDI-PC\Desktop\backend\250729_final project\venv\Lib\site-packages\django\db\models\fields\related_descriptors.py", line 394, in __set__
    super().__set__(instance, value)
    ~~~~~~~~~~~~~~~^^^^^^^^^^^^^^^^^
  File "C:\Users\MIDI-PC\Desktop\backend\250729_final project\venv\Lib\site-packages\django\db\models\fields\related_descriptors.py", line 291, in __set__
    raise ValueError(
    ...<7 lines>...
    )
ValueError: Cannot assign "'User 1'": "UserProfile.user" must be a "User" instance.